Workbook

Sheet README
A1: 東アジア歴史認識コーパス — データブック
A2: 日本・韓国・中国政府の歴史認識関連公式発話 コーディングデータ(2026-09-23時点)
A4: このブックの構成
A5: README | B5: このシート。
A6: Summary_Stats | B6: 国別・発話者レベル別の集計(すべてMainAxis_101シートを参照する数式)。データを修正すると自動で再計算される。
A7: Sources_102 | B7: 主軸101件+歴史的画期1件、計102件それぞれについて、本文を取得した一次資料URL(および代替取得したアーカイブURL)を一覧化。
A8: MainAxis_101 | B8: 本編の主軸コーパス。2020-2026年、日本41件(首脳HEAD 37+外務大臣級MINISTER 4)・韓国30件・中国30件、計101件。全件、原文を読んだうえで手動コーディング済み(classification_confidence=HIGH/MEDIUM)。
A9: LandmarkAnchor_1 | B9: 歴史的画期(landmark anchor)として別枠で扱う1995年村山談話。主軸とは異なる目的的サンプリング(時系列分析用ではなく参照点)。
A10: BacklogReview_718 | B10: 日本側の未採用候補718件の全数レビュー結果。full_review_status列がPROMOTED(7件、MainAxis_101に採用済み)/EXCLUDED(711件、理由をfull_review_reason列に記録)。
A12: 元データファイル(リポジトリ toruoga/toruoga)
A13: pilot_east_asia_2020_2025.csv | B13: MainAxis_101 シートの元CSV。
A14: landmark_anchors.csv | B14: LandmarkAnchor_1 シートの元CSV。
A15: pilot_manual_review.csv | B15: BacklogReview_718 シートの元CSV。
A16: pilot_japan_2020_2025.csv | B16: 日本のみの主軸データ(pilot_east_asia_2020_2025.csvの日本分と同一内容)。
A17: codebook.md | B17: コーディング基準の全定義(争点区分・発話者レベル・Kingdon三次元・謝罪語彙6項目等)。
A18: pilot_coverage_report.md | B18: 収集・コーディング手法、交絡チェックの全過程を記録した作業ログ(このデータブックの元)。
A19: draft_paper_ja.md / draft_paper_ja.docx | B19: 本データに基づく論文ドラフト(『法政論叢』投稿用)。
A20: scripts/phase2_keyness_analysis.py | B20: Summary_Statsシートのキーネス分析表を生成したスクリプト。
A22: 主要列の定義(codebook.mdより抜粋)
A23: record_id | B23: レコード一意識別子(UUID)。
A24: country | B24: japan / korea / china。
A25: speaker_level | B25: HEAD(首脳:大統領・首相・国家主席)/ MINISTER(外務大臣級)/ OFFICIAL(報道官等の実務レベル)/ UNKNOWN(第三者的報道等)。
A26: document_type | B26: STATEMENT / PRESS_CONFERENCE / SPEECH / JOINT_STATEMENT / WRITTEN_RESPONSE / OTHER。
A27: issue_primary | B27: WAR_GENERAL / AGGRESSION / COLONIAL_RULE / COMFORT_WOMEN / SEXUAL_SLAVERY / NANJING / YASUKUNI / HISTORY_TEXTBOOK / FORCED_LABOR / COMPENSATION_REPARATION / APOLOGY_GENERAL / HISTORICAL_RECOGNITION_GENERAL / OTHER。
A28: kingdon_problem / kingdon_policy / kingdon_politics | B28: Kingdonの政策の窓モデルの三次元。当該発話がその次元に該当するか(0/1)。
A29: apology / explanation / remorse / reflection / remedy / pardon_or_forgiveness | B29: 謝罪関連語彙6項目(0/1)。全文読解に基づき判定、キーワード一致のみでは判定しない。
A30: responsibility_actor | B30: STATE / GOVERNMENT / LEADER / MILITARY / PEOPLE_NATION / UNSPECIFIED / OTHER / NA。
A31: agency_explicit | B31: 行為主体(誰が加害したか)が明示されているか(0/1、日本に一切言及しない発話はNA)。
A32: classification_confidence | B32: HIGH / MEDIUM / LOW。一次資料への直接アクセスが失敗し通信社報道で代替した記録はMEDIUM。
A33: coder_notes | B33: コーディング根拠・出典・留保事項を記した自由記述(すべての境界事例の判断根拠を含む)。
A34: source_url / archive_url | B34: 一次資料のURL。ライブサイトが遮断されている場合はarchive_urlにWayback Machineスナップショットを記録。
A36: コーディング方針の要点
A37: ・非ハルシネーション原則:実際にダウンロード・全文読解した文書のみを記録。判定不能な項目はUNKNOWN/NAとし、推測で埋めない。
A38: ・対外発信用の英語公式文書のみを対象(各国国内向け原語言説は対象外)。
A39: ・日本:首相官邸(kantei.go.jp)アーカイブの網羅的クロール+外務省(mofa.go.jp、ライブ遮断のためWayback Machine経由)のMINISTER級4件。
A40: ・韓国・中国:サイト構造上の制約(JS動的読み込み、アーカイブの遡及範囲上限等)により、目的的サンプリング(比較政治学の構造化・焦点化比較の枠組みで正当化)。
A41: ・一部のKorea/China記録は、一次資料への直接アクセスが繰り返し失敗した場合に限り、一次資料を直接引用する通信社報道で代替(classification_confidence=MEDIUMに格下げ、coder_notesに明記)。

Sheet Summary_Stats
A1: 集計サマリー(すべて MainAxis_101 シートを参照する数式。データを追加・修正すると自動再計算される)
A2: 注:このシートの数式はExcelで開くと自動的に計算されます(この作業環境ではLibreOfficeの自動計算が機能しないため、ここでは事前計算していません)。数式のロジックはpilot_east_asia_2020_2025.csvに対する独立したPython集計と突き合わせて確認済みです(日本agency_explicit=0.0%、韓国71.4%、中国86.7%など、draft_paper_ja.mdの数値と一致)。
A4: 1. 国別 謝罪関連語彙6項目・行為主体明示率
A5: draft_paper_ja.md 6節(三)(四)の表に対応。agency_explicitのみNA(欠損)を分母から除外。
A6: 国 | B6: n | C6: apology | D6: explanation | E6: remorse | F6: reflection | G6: remedy | H6: pardon_or_forgiveness | I6: agency_explicit(NA除く)
A7: 日本 | B7: =COUNTIF('MainAxis_101'!$B$2:$B$102,"japan") | C7: =COUNTIFS('MainAxis_101'!$B$2:$B$102,"japan",'MainAxis_101'!$T$2:$T$102,"1")/COUNTIF('MainAxis_101'!$B$2:$B$102,"japan") | D7: =COUNTIFS('MainAxis_101'!$B$2:$B$102,"japan",'MainAxis_101'!$U$2:$U$102,"1")/COUNTIF('MainAxis_101'!$B$2:$B$102,"japan") | E7: =COUNTIFS('MainAxis_101'!$B$2:$B$102,"japan",'MainAxis_101'!$V$2:$V$102,"1")/COUNTIF('MainAxis_101'!$B$2:$B$102,"japan") | F7: =COUNTIFS('MainAxis_101'!$B$2:$B$102,"japan",'MainAxis_101'!$W$2:$W$102,"1")/COUNTIF('MainAxis_101'!$B$2:$B$102,"japan") | G7: =COUNTIFS('MainAxis_101'!$B$2:$B$102,"japan",'MainAxis_101'!$X$2:$X$102,"1")/COUNTIF('MainAxis_101'!$B$2:$B$102,"japan") | H7: =COUNTIFS('MainAxis_101'!$B$2:$B$102,"japan",'MainAxis_101'!$Y$2:$Y$102,"1")/COUNTIF('MainAxis_101'!$B$2:$B$102,"japan") | I7: =COUNTIFS('MainAxis_101'!$B$2:$B$102,"japan",'MainAxis_101'!$AA$2:$AA$102,"1")/COUNTIFS('MainAxis_101'!$B$2:$B$102,"japan",'MainAxis_101'!$AA$2:$AA$102,"<>NA")
A8: 韓国 | B8: =COUNTIF('MainAxis_101'!$B$2:$B$102,"korea") | C8: =COUNTIFS('MainAxis_101'!$B$2:$B$102,"korea",'MainAxis_101'!$T$2:$T$102,"1")/COUNTIF('MainAxis_101'!$B$2:$B$102,"korea") | D8: =COUNTIFS('MainAxis_101'!$B$2:$B$102,"korea",'MainAxis_101'!$U$2:$U$102,"1")/COUNTIF('MainAxis_101'!$B$2:$B$102,"korea") | E8: =COUNTIFS('MainAxis_101'!$B$2:$B$102,"korea",'MainAxis_101'!$V$2:$V$102,"1")/COUNTIF('MainAxis_101'!$B$2:$B$102,"korea") | F8: =COUNTIFS('MainAxis_101'!$B$2:$B$102,"korea",'MainAxis_101'!$W$2:$W$102,"1")/COUNTIF('MainAxis_101'!$B$2:$B$102,"korea") | G8: =COUNTIFS('MainAxis_101'!$B$2:$B$102,"korea",'MainAxis_101'!$X$2:$X$102,"1")/COUNTIF('MainAxis_101'!$B$2:$B$102,"korea") | H8: =COUNTIFS('MainAxis_101'!$B$2:$B$102,"korea",'MainAxis_101'!$Y$2:$Y$102,"1")/COUNTIF('MainAxis_101'!$B$2:$B$102,"korea") | I8: =COUNTIFS('MainAxis_101'!$B$2:$B$102,"korea",'MainAxis_101'!$AA$2:$AA$102,"1")/COUNTIFS('MainAxis_101'!$B$2:$B$102,"korea",'MainAxis_101'!$AA$2:$AA$102,"<>NA")
A9: 中国 | B9: =COUNTIF('MainAxis_101'!$B$2:$B$102,"china") | C9: =COUNTIFS('MainAxis_101'!$B$2:$B$102,"china",'MainAxis_101'!$T$2:$T$102,"1")/COUNTIF('MainAxis_101'!$B$2:$B$102,"china") | D9: =COUNTIFS('MainAxis_101'!$B$2:$B$102,"china",'MainAxis_101'!$U$2:$U$102,"1")/COUNTIF('MainAxis_101'!$B$2:$B$102,"china") | E9: =COUNTIFS('MainAxis_101'!$B$2:$B$102,"china",'MainAxis_101'!$V$2:$V$102,"1")/COUNTIF('MainAxis_101'!$B$2:$B$102,"china") | F9: =COUNTIFS('MainAxis_101'!$B$2:$B$102,"china",'MainAxis_101'!$W$2:$W$102,"1")/COUNTIF('MainAxis_101'!$B$2:$B$102,"china") | G9: =COUNTIFS('MainAxis_101'!$B$2:$B$102,"china",'MainAxis_101'!$X$2:$X$102,"1")/COUNTIF('MainAxis_101'!$B$2:$B$102,"china") | H9: =COUNTIFS('MainAxis_101'!$B$2:$B$102,"china",'MainAxis_101'!$Y$2:$Y$102,"1")/COUNTIF('MainAxis_101'!$B$2:$B$102,"china") | I9: =COUNTIFS('MainAxis_101'!$B$2:$B$102,"china",'MainAxis_101'!$AA$2:$AA$102,"1")/COUNTIFS('MainAxis_101'!$B$2:$B$102,"china",'MainAxis_101'!$AA$2:$AA$102,"<>NA")
A11: 2. 日本:発話者レベル別(HEAD=首脳 / MINISTER=外務大臣級)
A12: speaker_level | B12: n | C12: apology | D12: remorse | E12: reflection | F12: remedy | G12: agency_explicit
A13: HEAD | B13: =COUNTIFS('MainAxis_101'!$B$2:$B$102,"japan",'MainAxis_101'!$G$2:$G$102,"HEAD") | C13: =COUNTIFS('MainAxis_101'!$B$2:$B$102,"japan",'MainAxis_101'!$G$2:$G$102,"HEAD",'MainAxis_101'!$T$2:$T$102,"1")/COUNTIFS('MainAxis_101'!$B$2:$B$102,"japan",'MainAxis_101'!$G$2:$G$102,"HEAD") | D13: =COUNTIFS('MainAxis_101'!$B$2:$B$102,"japan",'MainAxis_101'!$G$2:$G$102,"HEAD",'MainAxis_101'!$V$2:$V$102,"1")/COUNTIFS('MainAxis_101'!$B$2:$B$102,"japan",'MainAxis_101'!$G$2:$G$102,"HEAD") | E13: =COUNTIFS('MainAxis_101'!$B$2:$B$102,"japan",'MainAxis_101'!$G$2:$G$102,"HEAD",'MainAxis_101'!$W$2:$W$102,"1")/COUNTIFS('MainAxis_101'!$B$2:$B$102,"japan",'MainAxis_101'!$G$2:$G$102,"HEAD") | F13: =COUNTIFS('MainAxis_101'!$B$2:$B$102,"japan",'MainAxis_101'!$G$2:$G$102,"HEAD",'MainAxis_101'!$X$2:$X$102,"1")/COUNTIFS('MainAxis_101'!$B$2:$B$102,"japan",'MainAxis_101'!$G$2:$G$102,"HEAD") | G13: =COUNTIFS('MainAxis_101'!$B$2:$B$102,"japan",'MainAxis_101'!$G$2:$G$102,"HEAD",'MainAxis_101'!$AA$2:$AA$102,"1")/COUNTIFS('MainAxis_101'!$B$2:$B$102,"japan",'MainAxis_101'!$G$2:$G$102,"HEAD")
A14: MINISTER | B14: =COUNTIFS('MainAxis_101'!$B$2:$B$102,"japan",'MainAxis_101'!$G$2:$G$102,"MINISTER") | C14: =COUNTIFS('MainAxis_101'!$B$2:$B$102,"japan",'MainAxis_101'!$G$2:$G$102,"MINISTER",'MainAxis_101'!$T$2:$T$102,"1")/COUNTIFS('MainAxis_101'!$B$2:$B$102,"japan",'MainAxis_101'!$G$2:$G$102,"MINISTER") | D14: =COUNTIFS('MainAxis_101'!$B$2:$B$102,"japan",'MainAxis_101'!$G$2:$G$102,"MINISTER",'MainAxis_101'!$V$2:$V$102,"1")/COUNTIFS('MainAxis_101'!$B$2:$B$102,"japan",'MainAxis_101'!$G$2:$G$102,"MINISTER") | E14: =COUNTIFS('MainAxis_101'!$B$2:$B$102,"japan",'MainAxis_101'!$G$2:$G$102,"MINISTER",'MainAxis_101'!$W$2:$W$102,"1")/COUNTIFS('MainAxis_101'!$B$2:$B$102,"japan",'MainAxis_101'!$G$2:$G$102,"MINISTER") | F14: =COUNTIFS('MainAxis_101'!$B$2:$B$102,"japan",'MainAxis_101'!$G$2:$G$102,"MINISTER",'MainAxis_101'!$X$2:$X$102,"1")/COUNTIFS('MainAxis_101'!$B$2:$B$102,"japan",'MainAxis_101'!$G$2:$G$102,"MINISTER") | G14: =COUNTIFS('MainAxis_101'!$B$2:$B$102,"japan",'MainAxis_101'!$G$2:$G$102,"MINISTER",'MainAxis_101'!$AA$2:$AA$102,"1")/COUNTIFS('MainAxis_101'!$B$2:$B$102,"japan",'MainAxis_101'!$G$2:$G$102,"MINISTER")
A16: 3. 韓国:発話者レベル別 agency_explicit明示率
A17: speaker_level | B17: n | C17: agency_explicit
A18: HEAD | B18: =COUNTIFS('MainAxis_101'!$B$2:$B$102,"korea",'MainAxis_101'!$G$2:$G$102,"HEAD",'MainAxis_101'!$AA$2:$AA$102,"<>NA") | C18: =COUNTIFS('MainAxis_101'!$B$2:$B$102,"korea",'MainAxis_101'!$G$2:$G$102,"HEAD",'MainAxis_101'!$AA$2:$AA$102,"1")/COUNTIFS('MainAxis_101'!$B$2:$B$102,"korea",'MainAxis_101'!$G$2:$G$102,"HEAD",'MainAxis_101'!$AA$2:$AA$102,"<>NA")
A19: OFFICIAL | B19: =COUNTIFS('MainAxis_101'!$B$2:$B$102,"korea",'MainAxis_101'!$G$2:$G$102,"OFFICIAL",'MainAxis_101'!$AA$2:$AA$102,"<>NA") | C19: =COUNTIFS('MainAxis_101'!$B$2:$B$102,"korea",'MainAxis_101'!$G$2:$G$102,"OFFICIAL",'MainAxis_101'!$AA$2:$AA$102,"1")/COUNTIFS('MainAxis_101'!$B$2:$B$102,"korea",'MainAxis_101'!$G$2:$G$102,"OFFICIAL",'MainAxis_101'!$AA$2:$AA$102,"<>NA")
A21: 3b. 韓国:大統領(HEAD)級 agency_explicit明示率、政権別
A22: 大統領(政権) | B22: n(NA除く) | C22: agency_explicit
A23: Moon Jae-in | B23: =COUNTIFS('MainAxis_101'!$B$2:$B$102,"korea",'MainAxis_101'!$E$2:$E$102,"Moon Jae-in",'MainAxis_101'!$AA$2:$AA$102,"<>NA") | C23: =COUNTIFS('MainAxis_101'!$B$2:$B$102,"korea",'MainAxis_101'!$E$2:$E$102,"Moon Jae-in",'MainAxis_101'!$AA$2:$AA$102,"1")/COUNTIFS('MainAxis_101'!$B$2:$B$102,"korea",'MainAxis_101'!$E$2:$E$102,"Moon Jae-in",'MainAxis_101'!$AA$2:$AA$102,"<>NA")
A24: Yoon Suk Yeol | B24: =COUNTIFS('MainAxis_101'!$B$2:$B$102,"korea",'MainAxis_101'!$E$2:$E$102,"Yoon Suk Yeol",'MainAxis_101'!$AA$2:$AA$102,"<>NA") | C24: =COUNTIFS('MainAxis_101'!$B$2:$B$102,"korea",'MainAxis_101'!$E$2:$E$102,"Yoon Suk Yeol",'MainAxis_101'!$AA$2:$AA$102,"1")/COUNTIFS('MainAxis_101'!$B$2:$B$102,"korea",'MainAxis_101'!$E$2:$E$102,"Yoon Suk Yeol",'MainAxis_101'!$AA$2:$AA$102,"<>NA")
A25: Lee Jae Myung | B25: =COUNTIFS('MainAxis_101'!$B$2:$B$102,"korea",'MainAxis_101'!$E$2:$E$102,"Lee Jae Myung",'MainAxis_101'!$AA$2:$AA$102,"<>NA") | C25: =COUNTIFS('MainAxis_101'!$B$2:$B$102,"korea",'MainAxis_101'!$E$2:$E$102,"Lee Jae Myung",'MainAxis_101'!$AA$2:$AA$102,"1")/COUNTIFS('MainAxis_101'!$B$2:$B$102,"korea",'MainAxis_101'!$E$2:$E$102,"Lee Jae Myung",'MainAxis_101'!$AA$2:$AA$102,"<>NA")
A27: 4. 中国:発話者レベル別 agency_explicit明示率
A28: speaker_level | B28: n | C28: agency_explicit
A29: HEAD | B29: =COUNTIFS('MainAxis_101'!$B$2:$B$102,"china",'MainAxis_101'!$G$2:$G$102,"HEAD") | C29: =COUNTIFS('MainAxis_101'!$B$2:$B$102,"china",'MainAxis_101'!$G$2:$G$102,"HEAD",'MainAxis_101'!$AA$2:$AA$102,"1")/COUNTIFS('MainAxis_101'!$B$2:$B$102,"china",'MainAxis_101'!$G$2:$G$102,"HEAD")
A30: OFFICIAL | B30: =COUNTIFS('MainAxis_101'!$B$2:$B$102,"china",'MainAxis_101'!$G$2:$G$102,"OFFICIAL") | C30: =COUNTIFS('MainAxis_101'!$B$2:$B$102,"china",'MainAxis_101'!$G$2:$G$102,"OFFICIAL",'MainAxis_101'!$AA$2:$AA$102,"1")/COUNTIFS('MainAxis_101'!$B$2:$B$102,"china",'MainAxis_101'!$G$2:$G$102,"OFFICIAL")
A31: UNKNOWN | B31: =COUNTIFS('MainAxis_101'!$B$2:$B$102,"china",'MainAxis_101'!$G$2:$G$102,"UNKNOWN") | C31: =COUNTIFS('MainAxis_101'!$B$2:$B$102,"china",'MainAxis_101'!$G$2:$G$102,"UNKNOWN",'MainAxis_101'!$AA$2:$AA$102,"1")/COUNTIFS('MainAxis_101'!$B$2:$B$102,"china",'MainAxis_101'!$G$2:$G$102,"UNKNOWN")
A33: 5. Kingdon三次元(問題・政策・政治)への該当率、国別
A34: 国 | B34: n | C34: kingdon_problem | D34: kingdon_policy | E34: kingdon_politics
A35: 日本 | B35: =COUNTIF('MainAxis_101'!$B$2:$B$102,"japan") | C35: =COUNTIFS('MainAxis_101'!$B$2:$B$102,"japan",'MainAxis_101'!$P$2:$P$102,"1")/COUNTIF('MainAxis_101'!$B$2:$B$102,"japan") | D35: =COUNTIFS('MainAxis_101'!$B$2:$B$102,"japan",'MainAxis_101'!$Q$2:$Q$102,"1")/COUNTIF('MainAxis_101'!$B$2:$B$102,"japan") | E35: =COUNTIFS('MainAxis_101'!$B$2:$B$102,"japan",'MainAxis_101'!$R$2:$R$102,"1")/COUNTIF('MainAxis_101'!$B$2:$B$102,"japan")
A36: 韓国 | B36: =COUNTIF('MainAxis_101'!$B$2:$B$102,"korea") | C36: =COUNTIFS('MainAxis_101'!$B$2:$B$102,"korea",'MainAxis_101'!$P$2:$P$102,"1")/COUNTIF('MainAxis_101'!$B$2:$B$102,"korea") | D36: =COUNTIFS('MainAxis_101'!$B$2:$B$102,"korea",'MainAxis_101'!$Q$2:$Q$102,"1")/COUNTIF('MainAxis_101'!$B$2:$B$102,"korea") | E36: =COUNTIFS('MainAxis_101'!$B$2:$B$102,"korea",'MainAxis_101'!$R$2:$R$102,"1")/COUNTIF('MainAxis_101'!$B$2:$B$102,"korea")
A37: 中国 | B37: =COUNTIF('MainAxis_101'!$B$2:$B$102,"china") | C37: =COUNTIFS('MainAxis_101'!$B$2:$B$102,"china",'MainAxis_101'!$P$2:$P$102,"1")/COUNTIF('MainAxis_101'!$B$2:$B$102,"china") | D37: =COUNTIFS('MainAxis_101'!$B$2:$B$102,"china",'MainAxis_101'!$Q$2:$Q$102,"1")/COUNTIF('MainAxis_101'!$B$2:$B$102,"china") | E37: =COUNTIFS('MainAxis_101'!$B$2:$B$102,"china",'MainAxis_101'!$R$2:$R$102,"1")/COUNTIF('MainAxis_101'!$B$2:$B$102,"china")
A39: 6. issue_primary(争点)分布、国別
A40: issue_primary | B40: 日本 | C40: 韓国 | D40: 中国
A41: WAR_GENERAL | B41: =COUNTIFS('MainAxis_101'!$B$2:$B$102,"japan",'MainAxis_101'!$N$2:$N$102,"WAR_GENERAL") | C41: =COUNTIFS('MainAxis_101'!$B$2:$B$102,"korea",'MainAxis_101'!$N$2:$N$102,"WAR_GENERAL") | D41: =COUNTIFS('MainAxis_101'!$B$2:$B$102,"china",'MainAxis_101'!$N$2:$N$102,"WAR_GENERAL")
A42: AGGRESSION | B42: =COUNTIFS('MainAxis_101'!$B$2:$B$102,"japan",'MainAxis_101'!$N$2:$N$102,"AGGRESSION") | C42: =COUNTIFS('MainAxis_101'!$B$2:$B$102,"korea",'MainAxis_101'!$N$2:$N$102,"AGGRESSION") | D42: =COUNTIFS('MainAxis_101'!$B$2:$B$102,"china",'MainAxis_101'!$N$2:$N$102,"AGGRESSION")
A43: COLONIAL_RULE | B43: =COUNTIFS('MainAxis_101'!$B$2:$B$102,"japan",'MainAxis_101'!$N$2:$N$102,"COLONIAL_RULE") | C43: =COUNTIFS('MainAxis_101'!$B$2:$B$102,"korea",'MainAxis_101'!$N$2:$N$102,"COLONIAL_RULE") | D43: =COUNTIFS('MainAxis_101'!$B$2:$B$102,"china",'MainAxis_101'!$N$2:$N$102,"COLONIAL_RULE")
A44: COMFORT_WOMEN | B44: =COUNTIFS('MainAxis_101'!$B$2:$B$102,"japan",'MainAxis_101'!$N$2:$N$102,"COMFORT_WOMEN") | C44: =COUNTIFS('MainAxis_101'!$B$2:$B$102,"korea",'MainAxis_101'!$N$2:$N$102,"COMFORT_WOMEN") | D44: =COUNTIFS('MainAxis_101'!$B$2:$B$102,"china",'MainAxis_101'!$N$2:$N$102,"COMFORT_WOMEN")
A45: SEXUAL_SLAVERY | B45: =COUNTIFS('MainAxis_101'!$B$2:$B$102,"japan",'MainAxis_101'!$N$2:$N$102,"SEXUAL_SLAVERY") | C45: =COUNTIFS('MainAxis_101'!$B$2:$B$102,"korea",'MainAxis_101'!$N$2:$N$102,"SEXUAL_SLAVERY") | D45: =COUNTIFS('MainAxis_101'!$B$2:$B$102,"china",'MainAxis_101'!$N$2:$N$102,"SEXUAL_SLAVERY")
A46: NANJING | B46: =COUNTIFS('MainAxis_101'!$B$2:$B$102,"japan",'MainAxis_101'!$N$2:$N$102,"NANJING") | C46: =COUNTIFS('MainAxis_101'!$B$2:$B$102,"korea",'MainAxis_101'!$N$2:$N$102,"NANJING") | D46: =COUNTIFS('MainAxis_101'!$B$2:$B$102,"china",'MainAxis_101'!$N$2:$N$102,"NANJING")
A47: YASUKUNI | B47: =COUNTIFS('MainAxis_101'!$B$2:$B$102,"japan",'MainAxis_101'!$N$2:$N$102,"YASUKUNI") | C47: =COUNTIFS('MainAxis_101'!$B$2:$B$102,"korea",'MainAxis_101'!$N$2:$N$102,"YASUKUNI") | D47: =COUNTIFS('MainAxis_101'!$B$2:$B$102,"china",'MainAxis_101'!$N$2:$N$102,"YASUKUNI")
...

Sheet Sources_102
A1: この一覧は、主軸コーパス101件+歴史的画期1件、計102件それぞれについて、本文を取得した一次資料URL(および、ライブサイト遮断時にWayback Machine等で代替取得した場合はそのアーカイブURL)を記載したもの。個々のレコードの詳細(response_text全文・coder_notes等)は MainAxis_101 / LandmarkAnchor_1 シートを参照。
A3: No. | B3: 国 | C3: 日付 | D3: 発話者 | E3: 発話者レベル | F3: 文書種別 | G3: 文書タイトル | H3: 一次資料URL | I3: アーカイブURL(Wayback等) | J3: 取得日 | K3: 収集方法 | L3: 確度 | M3: 区分
A4: 1 | B4: 中国 | C4: 2020-09-18 | D4: UNKNOWN | E4: UNKNOWN | F4: OTHER | G4: China commemorates 89th anniversary of the September 18 Incident | H4: https://news.cgtn.com/news/2020-09-18/Shenyang-commemorates-89th-anniversary-of-September-18-Incident--TSGXoRLqhy/index.html | J4: 2026-09-22 | K4: GOVCN_NEWS_ARCHIVE_WEB_SEARCH | L4: HIGH
A5: 2 | B5: 中国 | C5: 2021-07-07 | D5: UNKNOWN | E5: UNKNOWN | F5: OTHER | G5: China commemorates 84th anniversary of the Lugou (Marco Polo) Bridge Incident | H5: https://www.globaltimes.cn/page/202107/1228040.shtml | J5: 2026-09-22 | K5: GOVCN_NEWS_ARCHIVE_WEB_SEARCH | L5: HIGH
A6: 3 | B6: 中国 | C6: 2021-08-15 | D6: Hua Chunying | E6: OFFICIAL | F6: PRESS_CONFERENCE | G6: Foreign Ministry Spokesperson Hua Chunying's Remarks on Yasukuni Shrine | H6: https://tl.china-embassy.gov.cn/eng/fyrth/202108/t20210815_8909776.htm | J6: 2026-09-22 | K6: MFA_CHINA_DIRECT_FETCH_WEB_SEARCH | L6: HIGH
A7: 4 | B7: 中国 | C7: 2021-12-13 | D7: UNKNOWN | E7: UNKNOWN | F7: OTHER | G7: China holds national memorial ceremony for Nanjing Massacre victims (eighth) | H7: https://english.www.gov.cn/news/topnews/202112/13/content_WS61b6e2c1c6d09c94e48a2271.html | J7: 2026-09-22 | K7: GOVCN_NEWS_ARCHIVE_WEB_SEARCH | L7: HIGH
A8: 5 | B8: 中国 | C8: 2022-08-14 | D8: Wang Wenbin | E8: OFFICIAL | F8: PRESS_CONFERENCE | G8: Foreign Ministry Spokesperson Wang Wenbin's Remarks on Yasukuni Shrine | H8: https://www.fmprc.gov.cn/eng./xw/fyrbt/fyrbt/202405/t20240530_11349753.html | J8: 2026-09-22 | K8: MFA_CHINA_DIRECT_FETCH_WEB_SEARCH | L8: HIGH
A9: 6 | B9: 中国 | C9: 2022-08-15 | D9: Wang Wenbin | E9: OFFICIAL | F9: PRESS_CONFERENCE | G9: Foreign Ministry Spokesperson Wang Wenbin's Regular Press Conference on August 15, 2022 | H9: https://www.mfa.gov.cn/eng/xw/fyrbt/lxjzh/202405/t20240530_11347346.html | J9: 2026-09-22 | K9: MANUAL_TARGETED_DATE_SEARCH | L9: HIGH
A10: 7 | B10: 中国 | C10: 2022-11-17 | D10: Xi Jinping | E10: HEAD | F10: OTHER | G10: President Xi Jinping Meets with Japanese Prime Minister Fumio Kishida (Bangkok, APEC) | H10: https://www.fmprc.gov.cn/mfa_eng/zy/jj/2022/cxesgjtytjhtg/202211/t20221118_10977309.html | J10: 2026-09-22 | K10: MFA_CHINA_DIRECT_FETCH_WEB_SEARCH | L10: MEDIUM
A11: 8 | B11: 中国 | C11: 2022-12-13 | D11: UNKNOWN | E11: UNKNOWN | F11: OTHER | G11: China holds national memorial ceremony for Nanjing Massacre victims (ninth) | H11: https://english.www.gov.cn/news/topnews/202212/13/content_WS6397f285c6d0a757729e467f.html | J11: 2026-09-22 | K11: GOVCN_NEWS_ARCHIVE_WEB_SEARCH | L11: HIGH
A12: 9 | B12: 中国 | C12: 2023-07-07 | D12: UNKNOWN | E12: UNKNOWN | F12: OTHER | G12: China commemorates 86th anniversary of the Lugou (Marco Polo) Bridge Incident | H12: https://news.cgtn.com/news/2023-07-07/Remembering-Lugou-Bridge-Incident-and-Japan-s-war-crimes-1lfs1zncJTa/index.html | J12: 2026-09-22 | K12: GOVCN_NEWS_ARCHIVE_WEB_SEARCH | L12: HIGH
A13: 10 | B13: 中国 | C13: 2023-09-18 | D13: UNKNOWN | E13: UNKNOWN | F13: OTHER | G13: China commemorates 92nd anniversary of the September 18 Incident | H13: https://english.www.gov.cn/news/202309/18/content_WS65090967c6d0868f4e8df8f7.html | J13: 2026-09-22 | K13: GOVCN_NEWS_ARCHIVE_WEB_SEARCH | L13: HIGH
A14: 11 | B14: 中国 | C14: 2023-10-17 | D14: Mao Ning | E14: OFFICIAL | F14: PRESS_CONFERENCE | G14: Foreign Ministry Spokesperson Mao Ning’s Regular Press Conference on October 17, 2023_Ministry of Foreign Affairs of the People's Republic of China | H14: https://www.mfa.gov.cn/eng/xw/fyrbt/lxjzh/202405/t20240530_11347616.html | J14: NA | K14: (直接クロール、パイプライン01-09段階) | L14: HIGH
A15: 12 | B15: 中国 | C15: 2023-11-16 | D15: Xi Jinping | E15: HEAD | F15: OTHER | G15: Xi meets Kishida, reaffirming strategic and mutually beneficial relations (San Francisco, APEC) | H15: https://www.globaltimes.cn/page/202311/1302045.shtml | J15: 2026-09-22 | K15: MFA_CHINA_DIRECT_FETCH_WEB_SEARCH | L15: MEDIUM
... A33: 30 | B33: 中国 | C33: 2026-08-15 | D33: MOFA Spokesperson | E33: OFFICIAL | F33: OTHER | G33: Explainer: Yasukuni is a shrine for Japanese war criminals (Xinhua, quoting MOFA reaction to Aug 2026 visits) | H33: https://english.news.cn/20260819/ccc6afb34e874620bf95fd1bf57c8d7f/c.html | J33: 2026-09-22 | K33: WIRE_SERVICE_QUOTE_WEB_SEARCH | L33: MEDIUM
A34: 31 | B34: 日本 | C34: 1995-08-15 | D34: MURAYAMA Tomiichi | E34: HEAD | F34: STATEMENT | G34: Statement by Prime Minister Tomiichi Murayama "On the occasion of the 50th anniversary of the war's end" (15 August 1995) | H34: https://www.mofa.go.jp/announce/press/pm/murayama/9508.html | I34: https://web.archive.org/web/20260905165251/https://www.mofa.go.jp/announce/press/pm/murayama/9508.html | J34: 2026-09-22 | K34: WAYBACK_MANUAL_LANDMARK_ANCHOR | L34: HIGH | M34: 歴史的画期
A35: 32 | B35: 日本 | C35: 2020-05-19 | D35: MOTEGI Toshimitsu | E35: MINISTER | F35: PRESS_CONFERENCE | G35: Press Conference by Foreign Minister MOTEGI Toshimitsu (May 19, 2020) | H35: https://www.mofa.go.jp/press/kaiken/kaiken4e_000798.html | I35: https://web.archive.org/web/20251108125333id_/https://www.mofa.go.jp/press/kaiken/kaiken4e_000798.html | J35: 2026-09-22 | K35: MOFA_JAPAN_WAYBACK_MACHINE_FETCH | L35: HIGH
A36: 33 | B36: 日本 | C36: 2020-06-23 | D36: ABE Shinzo | E36: HEAD | F36: SPEECH | G36: Address by the Prime Minister for the Memorial Ceremony to Commemorate the Fallen on the 75th Anniversary of the End of the Battle of Okinawa | H36: https://japan.kantei.go.jp/98_abe/statement/201906/_00005.html | J36: 2026-09-22 | K36: MANUAL_REVIEW_BACKLOG | L36: HIGH
A37: 34 | B37: 日本 | C37: 2020-08-06 | D37: ABE Shinzo | E37: HEAD | F37: SPEECH | G37: Address by the Prime Minister at the Hiroshima Peace Memorial Ceremony | H37: https://japan.kantei.go.jp/98_abe/statement/202008/_00001.html | J37: 2026-09-22 | K37: KANTEI_ARCHIVE_KEYWORD_BACKLOG_REVIEW | L37: HIGH
A38: 35 | B38: 日本 | C38: 2020-08-09 | D38: ABE Shinzo | E38: HEAD | F38: SPEECH | G38: Address by the Prime Minister at the Nagasaki Peace Memorial Ceremony | H38: https://japan.kantei.go.jp/98_abe/statement/202008/_00002.html | J38: 2026-09-22 | K38: KANTEI_ARCHIVE_KEYWORD_BACKLOG_REVIEW | L38: HIGH
A39: 36 | B39: 日本 | C39: 2020-08-15 | D39: ABE Shinzo | E39: HEAD | F39: SPEECH | G39: Address by the Prime Minister at the Seventy-Fifth National Memorial Ceremony for the War Dead (Speeches and Statements by the Prime Minister) | Prime Minister of Japan and His Cabinet | H39: https://japan.kantei.go.jp/98_abe/statement/202008/_00003.html | J39: NA | K39: (直接クロール、パイプライン01-09段階) | L39: MEDIUM
A40: 37 | B40: 日本 | C40: 2021-01-08 | D40: SUGA Yoshihide | E40: HEAD | F40: PRESS_CONFERENCE | G40: Press Conference by the Prime Minister on the court case brought by a group of former comfort women (Speeches and Statements by the Prime Minister) | Prime Minister of Japan and His Cabinet | H40: https://japan.kantei.go.jp/99_suga/statement/202101/_00004.html | J40: NA | K40: (直接クロール、パイプライン01-09段階) | L40: HIGH
A41: 38 | B41: 日本 | C41: 2021-06-23 | D41: SUGA Yoshihide | E41: HEAD | F41: SPEECH | G41: Address by the Prime Minister for the Memorial Ceremony to Commemorate the Fallen on the 76th Anniversary of the End of the Battle of Okinawa | H41: https://japan.kantei.go.jp/99_suga/statement/202106/_00010.html | J41: 2026-09-22 | K41: MANUAL_REVIEW_BACKLOG | L41: HIGH
A42: 39 | B42: 日本 | C42: 2021-08-06 | D42: SUGA Yoshihide | E42: HEAD | F42: SPEECH | G42: Address by the Prime Minister at the Hiroshima Peace Memorial Ceremony | H42: https://japan.kantei.go.jp/99_suga/statement/202108/_00003.html | J42: 2026-09-22 | K42: KANTEI_ARCHIVE_KEYWORD_BACKLOG_REVIEW | L42: HIGH
A43: 40 | B43: 日本 | C43: 2021-08-09 | D43: SUGA Yoshihide | E43: HEAD | F43: SPEECH | G43: Address by the Prime Minister at the Nagasaki Peace Memorial Ceremony | H43: https://japan.kantei.go.jp/99_suga/statement/202108/_00004.html | J43: 2026-09-22 | K43: KANTEI_ARCHIVE_KEYWORD_BACKLOG_REVIEW | L43: HIGH
A44: 41 | B44: 日本 | C44: 2021-08-15 | D44: SUGA Yoshihide | E44: HEAD | F44: SPEECH | G44: Address by the Prime Minister at the Seventy-Sixth National Memorial Ceremony for the War Dead (Speeches and Statements by the Prime Minister) | Prime Minister of Japan and His Cabinet | H44: https://japan.kantei.go.jp/99_suga/statement/202108/_00006.html | J44: NA | K44: (直接クロール、パイプライン01-09段階) | L44: MEDIUM
A45: 42 | B45: 日本 | C45: 2021-10-15 | D45: KISHIDA Fumio | E45: HEAD | F45: PRESS_CONFERENCE | G45: Press Conference by the Prime Minister regarding Japan-ROK Telephone Summit Talks | H45: https://japan.kantei.go.jp/100_kishida/statement/202110/_00013.html | J45: 2026-09-22 | K45: MANUAL_REVIEW_BACKLOG | L45: HIGH
A46: 43 | B46: 日本 | C46: 2022-01-28 | D46: KISHIDA Fumio | E46: HEAD | F46: PRESS_CONFERENCE | G46: Press Conference by the Prime Minister regarding the Status of Consideration toward the Inscription on the World Cultural Heritage List of the Sado Complex of Heritage Mines, Primarily Gold Mines | H46: https://japan.kantei.go.jp/101_kishida/statement/202201/_00015.html | J46: 2026-09-22 | K46: MANUAL_REVIEW_BACKLOG | L46: HIGH
A47: 44 | B47: 日本 | C47: 2022-03-11 | D47: KISHIDA Fumio | E47: HEAD | F47: PRESS_CONFERENCE | G47: Press Conference on the Telephone Talk with Mr. YOON Suk Yeol, President-elect of the Republic of Korea | H47: https://japan.kantei.go.jp/101_kishida/statement/202203/_00010.html | J47: 2026-09-22 | K47: MANUAL_REVIEW_BACKLOG | L47: MEDIUM
A48: 45 | B48: 日本 | C48: 2022-05-10 | D48: HAYASHI Yoshimasa | E48: MINISTER | F48: PRESS_CONFERENCE | G48: Extraordinary Press Conference by Foreign Minister HAYASHI Yoshimasa (May 10, 2022, 3:29 p.m., Seoul) | H48: https://www.mofa.go.jp/press/kaiken/kaiken22e_000078.html | I48: https://web.archive.org/web/20230306220010id_/https://www.mofa.go.jp/press/kaiken/kaiken22e_000078.html | J48: 2026-09-22 | K48: MOFA_JAPAN_WAYBACK_MACHINE_FETCH | L48: HIGH
A49: 46 | B49: 日本 | C49: 2022-06-10 | D49: KISHIDA Fumio | E49: HEAD | F49: PRESS_CONFERENCE | G49: Press Conference by the Prime Minister on His Keynote Address at the Shangri-La Dialogue (the IISS Asia Security Summit) and Other Matters | H49: https://japan.kantei.go.jp/101_kishida/statement/202206/_00005.html | J49: 2026-09-22 | K49: MANUAL_REVIEW_BACKLOG | L49: HIGH
A50: 47 | B50: 日本 | C50: 2022-08-06 | D50: KISHIDA Fumio | E50: HEAD | F50: SPEECH | G50: Address by Prime Minister KISHIDA Fumio at the Hiroshima Peace Memorial Ceremony | H50: https://japan.kantei.go.jp/101_kishida/statement/202208/_00003.html | J50: 2026-09-22 | K50: KANTEI_ARCHIVE_KEYWORD_BACKLOG_REVIEW | L50: HIGH
A51: 48 | B51: 日本 | C51: 2022-08-09 | D51: KISHIDA Fumio | E51: HEAD | F51: SPEECH | G51: Address by Prime Minister KISHIDA Fumio at the Nagasaki Peace Memorial Ceremony | H51: https://japan.kantei.go.jp/101_kishida/statement/202208/_00004.html | J51: 2026-09-22 | K51: KANTEI_ARCHIVE_KEYWORD_BACKLOG_REVIEW | L51: HIGH
A52: 49 | B52: 日本 | C52: 2022-08-10 | D52: HAYASHI Yoshimasa | E52: MINISTER | F52: PRESS_CONFERENCE | G52: Press Conference by Foreign Minister HAYASHI Yoshimasa (August 10, 2022, 8:11 p.m.) | H52: https://www.mofa.go.jp/press/kaiken/kaiken24e_000151.html | I52: https://web.archive.org/web/20251203124600id_/https://www.mofa.go.jp/press/kaiken/kaiken24e_000151.html | J52: 2026-09-22 | K52: MOFA_JAPAN_WAYBACK_MACHINE_FETCH | L52: HIGH
A53: 50 | B53: 日本 | C53: 2022-08-15 | D53: KISHIDA Fumio | E53: HEAD | F53: SPEECH | G53: Address by Prime Minister Kishida at the Seventy-Seventh National Memorial Ceremony for the War Dead (Speeches and Statements <br>by the Prime Minister) | Prime Minister's Office of Japan | H53: https://japan.kantei.go.jp/101_kishida/statement/202208/_00006.html | J53: NA | K53: (直接クロール、パイプライン01-09段階) | L53: MEDIUM
A54: 51 | B54: 日本 | C54: 2022-11-13 | D54: KISHIDA Fumio | E54: HEAD | F54: PRESS_CONFERENCE | G54: Press Conference by Prime Minister Kishida regarding the ASEAN-related Summit Meetings and Other Matters | H54: https://japan.kantei.go.jp/101_kishida/statement/202211/_00007.html | J54: 2026-09-22 | K54: MANUAL_REVIEW_BACKLOG | L54: HIGH
A55: 52 | B55: 日本 | C55: 2023-03-06 | D55: KISHIDA Fumio | E55: HEAD | F55: PRESS_CONFERENCE | G55: Press Conference by the Prime Minister regarding the Issue of Former Civilian Workers from the Korean Peninsula (Speeches and Statements <br>by the Prime Minister) | Prime Minister's Office of Japan | H55: https://japan.kantei.go.jp/101_kishida/statement/202303/_00004.html | J55: NA | K55: (直接クロール、パイプライン01-09段階) | L55: HIGH
A56: 53 | B56: 日本 | C56: 2023-03-16 | D56: KISHIDA Fumio | E56: HEAD | F56: PRESS_CONFERENCE | G56: Joint Press Conference by the Leaders of Japan and the Republic of Korea (Speeches and Statements <br>by the Prime Minister) | Prime Minister's Office of Japan | H56: https://japan.kantei.go.jp/101_kishida/statement/202303/_00010.html | J56: NA | K56: (直接クロール、パイプライン01-09段階) | L56: HIGH
A57: 54 | B57: 日本 | C57: 2023-05-07 | D57: KISHIDA Fumio | E57: HEAD | F57: PRESS_CONFERENCE | G57: Japanese Prime Minister: 'my heart hurts' over forced laborers' suffering | H57: https://eng.president.go.kr/briefing/EtDV6ERL | I57: https://web.archive.org/web/20241204144009id_/https://eng.president.go.kr/briefing/EtDV6ERL | J57: 2026-09-22 | K57: WAYBACK_CDX_KOREA_PRESIDENTIAL_BRIEFING | L57: MEDIUM
A58: 55 | B58: 日本 | C58: 2023-06-23 | D58: KISHIDA Fumio | E58: HEAD | F58: SPEECH | G58: Address by Prime Minister KISHIDA Fumio for the Memorial Ceremony to Commemorate the Fallen on the 78th Anniversary of the End of the Battle of Okinawa | H58: https://japan.kantei.go.jp/101_kishida/statement/202306/0623okinawa.html | J58: 2026-09-22 | K58: MANUAL_REVIEW_BACKLOG | L58: HIGH
...

Sheet MainAxis_101
A1: record_id | B1: country | C1: date | D1: year | E1: speaker_name | F1: speaker_position | G1: speaker_level | H1: institution | I1: document_type | J1: document_title | K1: question_text | L1: response_text | M1: relevant_excerpt | N1: issue_primary | O1: issue_secondary | P1: kingdon_problem | Q1: kingdon_policy | R1: kingdon_politics | S1: kingdon_confidence | T1: apology | U1: explanation | V1: remorse | W1: reflection | X1: remedy | Y1: pardon_or_forgiveness | Z1: responsibility_actor | AA1: agency_explicit | AB1: audience_orientation | AC1: source_language | AD1: official_translation | AE1: source_url | AF1: retrieval_date | AG1: archive_url | AH1: collection_method | AI1: coder_notes | AJ1: classification_confidence | AK1: duplicate_group_id | AL1: canonical_record
A2: 37339e32-cd17-43ae-bc8b-654c9b92a7b0 | B2: japan | C2: 2022-08-15 | D2: 2022 | E2: KISHIDA Fumio | F2: Prime Minister of Japan | G2: HEAD | H2: Prime Minister's Office of Japan (Kantei) | I2: SPEECH | J2: Address by Prime Minister Kishida at the Seventy-Seventh National Memorial Ceremony for the War Dead (Speeches and Statements <br>by the Prime Minister) | Prime Minister's Office of Japan | L2: Address by Prime Minister Kishida at the Seventy-Seventh National Memorial Ceremony for the War Dead (Speeches and Statements <br>by the Prime Minister) | Prime Minister's Office of Japan Address by Prime Minister Kishida at the Seventy-Seventh National Memorial Ceremony for the War Dead August 15, 2022 Tweet [Provisional translation] In the gracious presence of Their Majesties the Emperor and Empress, and with the attendance of bereaved families of the war dead, distinguished representatives of all sectors of society, and many others, I hereby commence the annual National Memorial Ceremony for the War Dead. More than three million of our compatriots lost their lives during the war. Some fell on the battlefields worrying about the future of their homeland and wishing for the happiness of their families. Others perished in remote foreign countries after the war. And many fell victim to the violent turmoil of war in the atomic bombings of Hiroshima and Nagasaki, the air raids on numerous cities, and the ground battles in Okinawa, among others. Here, before the souls of all who lost their lives, I offer my heartfelt prayers for their repose. We will not forget, even for a moment, that the peace and prosperity we enjoy today was built atop the precious lives and the history of suffering of the war dead. I express my deepest respect and gratitude once more. Never will we forget the large number of war dead whose remains have still not been recovered. Taking it as the responsibility of the nation, we shall spare no effort to enable their remains to return to their hometowns at the earliest possible time. Since the end of the war, Japan has consistently walked the path of a peace-loving nation. Taking the lessons of history deeply into our hearts, we have made all possible efforts for world peace and prosperity. We must never again repeat the devastation of war. We will continue to remain committed to this resolute pledge. In this world in which conflicts have not yet ceased, under the banner of "Proactive Contribution to Peace," Japan is determined to join forces with the international community and do its utmost to resolve the various challenges facing the world. We shall carve out the future of our nation for the sake of the generation alive now and the generations of tomorrow. I will conclude my address by once again offering my heartfelt prayers for the repose of the souls of the war dead and for the happiness of the members of their bereaved families. KISHIDA Fumio Prime Minister of Japan August 15, 2022 More Related Link Japanese Tweet Archives (Archived entries for the 101st through 103rd Prime Ministers) The 103rd Prime Minister ISHIBA Shigeru Open Close 2025 2024 The 102nd Prime Minister ISHIBA Shigeru Open Close 2024 The 101st Prime Minister KISHIDA Fumio Open Close 2024 2023 2022 2021 Tag List View All Return to the Speeches and Statements by the Prime Minister | M2: Address by Prime Minister Kishida at the Seventy-Seventh National Memorial Ceremony for the War Dead (Speeches and Statements <br>by the Prime Minister) | Prime Minister's Office of Japan Address by Prime Minister Kishida at the Seventy-Seventh National Memorial Ceremony for the War Dead August 15, 2022 Tweet [Provisional translation] In the gracious presence of Their Majesties the Emperor and Empress, and with the attendance of bereaved families of the war dead, distinguished representatives of all sectors of society, and many others, I hereby commence the annual National Memorial Ceremony for the War Dead. More than three million of our compatriots lost their lives during the war. Some fell on the battlefields worrying about the future of their homeland and wishing for the happiness of their families. Others perished in remote foreign countries after the war. And many fell victim to the violent turmoil of war in the atomic bombings of Hiroshima and Nagasaki, the air raids on numerous cities, and the ground battles in Okinawa, among others. Here, before the souls of all who lost their lives, I offer my heartfelt prayers for their repose. We will not forget, even for a moment, that the peace and prosperity we enjoy today was built atop the precious lives and the history of suffering of the war dead. I express my deepest respect and gratitude once more. Never will we forget the large number of war dead whose remains have still not been recovered. Taking it as the responsibility of the nation, we shall spare no effort to enable their remains to return to their hometowns at the earliest possible time. Since the end of the war, Japan has consistently walked the path of a peace-loving nation. Taking the lessons of history deeply into our hearts, we have made all possible efforts for world peace and prosperity. We must never again repeat the devastation of war. We will continue to remain committed to this resolute pledge. In this world in which conflicts have not yet ceased, under the banner of "Proactive Contribution to Peace," Japan is determined to join forces with the international community and do its utmost to resolve the various challenges facing the world. We shall carve out the future of our nation for the sake of the generation alive now and the generations of tomorrow. I will conclude my address by once again offering my heartfelt prayers for the repose of the souls of the war dead and for the happiness of the members of their bereaved families. KISHIDA Fumio Prime Minister of Japan August 15, 2022 More Related Link Japanese Tweet Archives (Archived entries for the 101st through 103rd Prime Ministers) The 103rd Prime Minister ISHIBA Shigeru Open Close 2025 2024 The 102nd Prime Minister ISHIBA Shigeru Open Close 2024 The 101st Prime Minister KISHIDA Fumio Open Close 2024 2023 2022 2021 Tag List View All Return to the Speeches and Statements by the Prime Minister | N2: WAR_GENERAL | O2: NA | P2: 0 | Q2: 1 | R2: 0 | S2: MEDIUM | T2: 0 | U2: 0 | V2: 0 | W2: 1 | X2: 1 | Y2: 0 | Z2: UNSPECIFIED | AA2: 0 | AB2: DOMESTIC | AC2: en | AD2: 1 | AE2: https://japan.kantei.go.jp/101_kishida/statement/202208/_00006.html | AF2: NA | AG2: NA | AH2: NA | AI2: 77th National Memorial Ceremony for the War Dead (Kishida's first). Adds "taking the lessons of history deeply into our hearts" but still no apology/remorse toward foreign victims. | AJ2: MEDIUM | AK2: 6d37ea79-403b-52b7-a520-3f8875766af8 | AL2: 1
A3: e7c2f241-4e6c-44d2-8461-4db00c0314ab | B3: japan | C3: 2023-03-06 | D3: 2023 | E3: KISHIDA Fumio | F3: Prime Minister of Japan | G3: HEAD | H3: Prime Minister's Office of Japan (Kantei) | I3: PRESS_CONFERENCE | J3: Press Conference by the Prime Minister regarding the Issue of Former Civilian Workers from the Korean Peninsula (Speeches and Statements <br>by the Prime Minister) | Prime Minister's Office of Japan | L3: Press Conference by the Prime Minister regarding the Issue of Former Civilian Workers from the Korean Peninsula (Speeches and Statements <br>by the Prime Minister) | Prime Minister's Office of Japan #DiplomacySecurity Press Conference by the Prime Minister regarding the Issue of Former Civilian Workers from the Korean Peninsula March 6, 2023 Tweet [Provisional translation] [Provisional translation] (On the Government’s reaction to the issue of former civilian workers from the Korean Peninsula, the Japan-ROK Summit Meeting and his historic recognition of the Japan-ROK relations) Earlier today, the Government of the Republic of Korea (ROK) announced their measures regarding the issue of former civilian workers from the Korean Peninsula. We regard the latest measures announced by the Government of ROK as a step towards restoring healthy Japan-ROK relations. ROK President Yoon Suk Yeol and I have been in communication on various occasions, including our meeting in New York and the Japan-ROK Summit Meeting in Cambodia. I believe that Japan and the ROK are important neighboring countries in addressing various issues in the international community, and in light of the current international situation and strategic environment, we recognize the importance of Japan-ROK and Japan-U.S.-ROK cooperation, as well as the importance of cooperation with the ROK in working toward a Free and Open Indo-Pacific. We intend to closely communicate with President Yoon down the road. Regarding the question about a future Japan-ROK Summit Meeting, we have not yet decided on any specific diplomatic schedule in Japan-ROK relations. We have taken over the position of previous cabinets on the recognition of the history, including the Japan-ROK Joint Declaration announced in October 1998. This is the position that the Government of Japan takes. (On his thoughts on ensuring the irreversibility) We regard the measures announced today by the Government of ROK as a step towards restoring healthy Japan-ROK relations. We understand that the Government of ROK has also made various efforts on its part. We have high hopes that this could be an opportunity to strengthen and strongly advance Japan-ROK relations while implementing the measures. To this end, I would like to emphasize the importance of communicating closely with President Yoon. (On whether the concerns over possible reversal on the irreversibility has been eliminated) I would like to refrain from going into a hypothetical question. We appreciate the announced measures and hope that Japan-ROK relations will move forward. To that end, we will continue to communicate with each other. (On the Japan-ROK Export Control Policy Dialogue) Let me first clarify that the "update of licensing policies and procedures on exports of controlled items to the ROK" has been conducted to ensure proper implementation of export control from a security perspective and therefore is a separate issue from the issue of former civilian workers from the Korean Peninsula. And today, I have been informed that in order to restore the pre-July 2019 status quo regarding the pending issue of export control, both sides have decided to promptly hold related bilateral consultations between the Japanese and ROK authorities, in light of the ROK's announcement of its decision to suspend its WTO dispute settlement procedures. I hope that the consultations will proceed steadily. For further details, the Ministry of Economy, Trade and Industry is ready to answer your questions. More Related Link Japanese Tweet Archives (Archived entries for the 101st through 103rd Prime Ministers) The 103rd Prime Minister ISHIBA Shigeru Open Close 2025 2024 The 102nd Prime Minister ISHIBA Shigeru Open Close 2024 The 101st Prime Minister KISHIDA Fumio Open Close 2024 2023 2022 2021 Tag List View All Related Pages Return to the Speeches and Statements by the Prime Minister | M3: Press Conference by the Prime Minister regarding the Issue of Former Civilian Workers from the Korean Peninsula (Speeches and Statements <br>by the Prime Minister) | Prime Minister's Office of Japan #DiplomacySecurity Press Conference by the Prime Minister regarding the Issue of Former Civilian Workers from the Korean Peninsula March 6, 2023 Tweet [Provisional translation] [Provisional translation] (On the Government’s reaction to the issue of former civilian workers from the Korean Peninsula, the Japan-ROK Summit Meeting and his historic recognition of the Japan-ROK relations) Earlier today, the Government of the Republic of Korea (ROK) announced their measures regarding the issue of former civilian workers from the Korean Peninsula. We regard the latest measures announced by the Government of ROK as a step towards restoring healthy Japan-ROK relations. ROK President Yoon Suk Yeol and I have been in communication on various occasions, including our meeting in New York and the Japan-ROK Summit Meeting in Cambodia. I believe that Japan and the ROK are important neighboring countries in addressing various issues in the international community, and in light of the current international situation and strategic environment, we recognize the importance of Japan-ROK and Japan-U.S.-ROK cooperation, as well as the importance of cooperation with the ROK in working toward a Free and Open Indo-Pacific. We intend to closely communicate with President Yoon down the road. Regarding the question about a future Japan-ROK Summit Meeting, we have not yet decided on any specific diplomatic schedule in Japan-ROK relations. We have taken over the position of previous cabinets on the recognition of the history, including the Japan-ROK Joint Declaration announced in October 1998. This is the position that the Government of Japan takes. (On his thoughts on ensuring the irreversibility) We regard the measures announced today by the Government of ROK as a step towards restoring healthy Japan-ROK relations. We understand that the Government of ROK has also made various efforts on its part. We have high hopes that this could be an opportunity to strengthen and strongly advance Japan-ROK relations while implementing the measures. To this end, I would like to emphasize the importance of communicating closely with President Yoon. (On whether the concerns over possible reversal on the irreversibility has been eliminated) I would like to refrain from going into a hypothetical question. We appreciate the announced measures and hope that Japan-ROK relations will move forward. To that end, we will continue to communicate with each other. (On the Japan-ROK Export Control Policy Dialogue) Let me first clarify that the "update of licensing policies and procedures on exports of controlled items to the ROK" has been conducted to ensure proper implementation of export control from a security perspective and therefore is a separate issue from the issue of former civilian workers from the Korean Peninsula. | N3: FORCED_LABOR | O3: COMPENSATION_REPARATION;HISTORICAL_RECOGNITION_GENERAL | P3: 1 | Q3: 1 | R3: 1 | S3: HIGH | T3: 0 | U3: 1 | V3: 0 | W3: 0 | X3: 1 | Y3: 0 | Z3: UNSPECIFIED | AA3: 0 | AB3: MIXED | AC3: en | AD3: 1 | AE3: https://japan.kantei.go.jp/101_kishida/statement/202303/_00004.html | AF3: NA | AG3: NA | AH3: NA | AI3: Kishida's reaction to the ROK government's March 2023 third-party reimbursement plan for wartime forced-labor court judgments against Japanese firms. Cites the Oct 1998 Japan-ROK Joint Declaration (Obuchi-Kim) as the standing "recognition of history" position by reference only, without re-quoting its apology/remorse language. remedy=1 refers to the ROK's own compensation measure, which Japan welcomes, not a new Japanese remedy. | AJ3: HIGH | AK3: fcb0a3eb-0570-5882-8283-33e807cdb232 | AL3: 1
A4: da272986-2674-4610-864b-a25a61e8e58e | B4: japan | C4: 2023-03-16 | D4: 2023 | E4: KISHIDA Fumio | F4: Prime Minister of Japan | G4: HEAD | H4: Prime Minister's Office of Japan (Kantei) | I4: PRESS_CONFERENCE | J4: Joint Press Conference by the Leaders of Japan and the Republic of Korea (Speeches and Statements <br>by the Prime Minister) | Prime Minister's Office of Japan | L4: Joint Press Conference by the Leaders of Japan and the Republic of Korea (Speeches and Statements <br>by the Prime Minister) | Prime Minister's Office of Japan #DiplomacySecurity #JPNKORsummit #FreeOpenIndoPacific #AbductionsByNK #NKmissile Joint Press Conference by the Leaders of Japan and the Republic of Korea March 16, 2023 Tweet [Provisional translation] [Opening Statement by Prime Minister KISHIDA Fumio] I welcome President YOON Suk Yeol of the Republic of Korea (ROK) most wholeheartedly in his visit to Japan. This week, in Tokyo the cherry blossoms have come into full bloom, and now, as we emerge from a long period of winter, we welcome the President of the ROK to Japan as the first bilateral visit in roughly 12 years. In my meeting with President Yoon, we were in full agreement that the strengthening of Japan-ROK relations is a matter of pressing urgency in the current strategic environment, and that we will further develop Japan-ROK relations, based on the foundation of the friendly and cooperative relations we have cultivated since the normalization of our diplomatic relations in 1965. Recently, the ROK Government announced measures regarding the issue of former civilian workers from the Korean Peninsula. The Government of Japan commends these measures as a step towards restoring healthy Japan-ROK relations, which have been in extremely severe circumstances. During our summit meeting, we confirmed that the Government of Japan takes up in its entirety the position of previous cabinets on the recognition of the history, including the Japan-ROK Joint Declaration announced in October 1998. I look forward to a robust expansion of exchanges between our two countries in the future in such fields as politics, the economy, and culture, alongside the implementation of these measures. In order to open up a new chapter in Japan-ROK relations, during the meeting I held with President Yoon today, we agreed to restart "shuttle diplomacy," with the leaders of our nations each frequently visiting the other's country, regardless of the form in which those visits take place. In addition, with regard to Japan-ROK relations, we agreed to invigorate communications between our governments across a wide range of fields. In concrete terms, first of all, we shared the same stance that we will restart at an early time the Japan-ROK Security Dialogue and also the Japan-ROK Vice-Ministerial Strategic Dialogue, both of which have been suspended for a long time, and we agreed on the importance of relaunching the high-level Japan-ROK-China trilateral process at an early time. We also decided to launch consultations between Japan and the ROK regarding economic security. In addition, we made progress in the area of export control. In the future we will promote a wide range of dialogue in various policy areas between our respective ministries and agencies in charge. In addition, private sector exchanges and cooperation are a framework supporting bilateral relations. I welcome the fact that, taking the opportunity of President Yoon's visit to Japan, economic federations in both Japan and the ROK have announced they will each establish a fund for future-oriented Japan-ROK cooperation and exchange. The Government of Japan will continue to support exchanges among young people, who will hold the key to our nations' futures. Exchanges between our two countries have now recovered, and as for the number of foreign visitors to our two countries, it is ROK and Japanese nationals that are each visiting the other's country in the greatest number. I very much look forward to a further acceleration of the virtuous cycle of increasingly active people-to-people exchanges and improvements in our relations. President Yoon and I also shared a common recognition of the current harsh security environment. In particular, with regard to responses to North Korea, which is further pursuing nuclear and missile activities, including this morning's launch of an ICBM-class ballistic missile, we confirmed the importance of further reinforcing the deterrence and response capabilities of the Japan-U.S. Alliance and ROK-U.S. Alliance and of vigorously promoting security cooperation both between Japan and the ROK and among Japan, the ROK, and the U.S. The window for dialogue with North Korea remains open. That fact has not changed. President Yoon also expressed strong support once again regarding the abductions issue. Moreover, we reaffirmed the importance of bringing about a free and open Indo-Pacific at this historic turning point, and we shared a common recognition of the importance of like-minded countries working together to fully defend the free and open international order based on the rule of law. This visit by President Yoon to Japan has been a major step forward for the normalization of Japan-ROK relations. I am looking forward to the opportunity to speak in even greater depth with President Yoon and the First Lady at the dinner scheduled to take place after this. With President Yoon's visit to Japan as a turning point, I have high hopes for us to cultivate our trust and friendship and for Japan-ROK relations to make great strides forward. More Related Link Photos (PM in Action) Summary Japanese Tweet Archives (Archived entries for the 101st through 103rd Prime Ministers) The 103rd Prime Minister ISHIBA Shigeru Open Close 2025 2024 The 102nd Prime Minister ISHIBA Shigeru Open Close 2024 The 101st Prime Minister KISHIDA Fumio Open Close 2024 2023 2022 2021 Tag List View All Related Pages Return to the Speeches and Statements by the Prime Minister | M4: In my meeting with President Yoon, we were in full agreement that the strengthening of Japan-ROK relations is a matter of pressing urgency in the current strategic environment, and that we will further develop Japan-ROK relations, based on the foundation of the friendly and cooperative relations we have cultivated since the normalization of our diplomatic relations in 1965. Recently, the ROK Government announced measures regarding the issue of former civilian workers from the Korean Peninsula. The Government of Japan commends these measures as a step towards restoring healthy Japan-ROK relations, which have been in extremely severe circumstances. During our summit meeting, we confirmed that the Government of Japan takes up in its entirety the position of previous cabinets on the recognition of the history, including the Japan-ROK Joint Declaration announced in October 1998. I look forward to a robust expansion of exchanges between our two countries in the future in such fields as politics, the economy, and culture, alongside the implementation of these measures. In order to open up a new chapter in Japan-ROK relations, during the meeting I held with President Yoon today, we agreed to restart "shuttle diplomacy," with the leaders of our nations each frequently visiting the other's country, regardless of the form in which those visits take place. In addition, with regard to Japan-ROK relations, we agreed to invigorate communications between our governments across a wide range of fields. In the future we will promote a wide range of dialogue in various policy areas between our respective ministries and agencies in charge. In addition, private sector exchanges and cooperation are a framework supporting bilateral relations. I welcome the fact that, taking the opportunity of President Yoon's visit to Japan, economic federations in both Japan and the ROK have announced they will each establish a fund for future-oriented Japan-ROK cooperation and exchange. The Government of Japan will continue to support exchanges among young people, who will hold the key to our nations' futures. Exchanges between our two countries have now recovered, and as for the number of foreign visitors to our two countries, it is ROK and Japanese nationals that are each visiting the other's country in the greatest number. I very much look forward to a further acceleration of the virtuous cycle of increasingly active people-to-people exchanges and improvements in our relations. President Yoon and I also shared a common recognition of the current harsh security environment. In particular, with regard to responses to North Korea, which is further pursuing nuclear and missile activities, including this morning's launch of an ICBM-class ballistic missile, we confirmed the importance of further reinforcing the deterrence and response capabilities of the Japan-U.S. President Yoon also expressed strong support once again regarding the abductions issue. Moreover, we reaffirmed the importance of bringing about a free and open Indo-Pacific at this historic turning point, and we shared a common recognition of the importance of like-minded countries working together to fully defend the free and open international order based on the rule of law. This visit by President Yoon to Japan has been a major step forward for the normalization of Japan-ROK relations. I am looking forward to the opportunity to speak in even greater depth with President Yoon and the First Lady at the dinner scheduled to take place after this. With President Yoon's visit to Japan as a turning point, I have high hopes for us to cultivate our trust and friendship and for Japan-ROK relations to make great strides forward. More Related Link Photos (PM in Action) Summary Japanese Tweet Archives (Archived entries for the 101st through 103rd Prime Ministers) The 103rd Prime Minister ISHIBA Shigeru Open Close 2025 2024 The 102nd Prime Minister ISHIBA Shigeru Open Close 2024 The 101st Prime Minister KISHIDA Fumio Open Close 2024 2023 2022 2021 Tag List View All Related Pages Return to the Speeches and Statements by the Prime Minister | N4: FORCED_LABOR | O4: HISTORICAL_RECOGNITION_GENERAL | P4: 1 | Q4: 1 | R4: 1 | S4: HIGH | T4: 0 | U4: 1 | V4: 0 | W4: 0 | X4: 1 | Y4: 0 | Z4: UNSPECIFIED | AA4: 0 | AB4: MIXED | AC4: en | AD4: 1 | AE4: https://japan.kantei.go.jp/101_kishida/statement/202303/_00010.html | AF4: NA | AG4: NA | AH4: NA | AI4: Opening statement, joint press conference with ROK President Yoon Suk Yeol marking the restart of "shuttle diplomacy" (first bilateral visit in ~12 years). Confirms Japan "takes up in its entirety the position of previous cabinets on the recognition of the history, including the Japan-ROK Joint Declaration announced in October 1998" -- by reference only, no apology/remorse language re-quoted directly. Coded from the opening statement only; the source page may contain a following Q&A section not captured by the automated Q&A splitter (no "Question:"-style markers) -- flagged for a follow-up pass. | AJ4: HIGH | AK4: 572c38b4-5546-595a-afd6-e20a9c92e73a | AL4: 1
